<mujoco model="airbot_play">
  <asset>
    <texture name="grid" type="2d" builtin="checker" rgb1=".9 .8 .7" rgb2=".4 .4 .4" width="300" height="300" mark="edge" markrgb=".2 .3 .4"/>
    <material name="grid" texture="grid" texrepeat="2 2" texuniform="true" reflectance=".2"/>
  </asset>
  <visual>
    <global offwidth="1920" offheight="1080"/>
    <quality shadowsize="4096" offsamples="4"/>
    <headlight ambient="0.4 0.4 0.4"/>
    <scale com="0.05" camera="0.06" framelength="0.5" framewidth="0.02" forcewidth="0.005" contactwidth="0.01" contactheight="0.05"/>
  </visual>

  <worldbody>
    <light directional='false' diffuse='.3 .3 .3' specular='0.3 0.3 0.3' pos='0.3 -0.3 3'/>
    <light directional='false' diffuse='.3 .3 .3' specular='0.3 0.3 0.3' pos='-0.3 0.3 3'/>
    <light directional='false' diffuse='.3 .3 .3' specular='0.3 0.3 0.3' pos='0.6 0.3 3'/>
    <geom name="ground" type="plane" pos="0 0 0" size="3 3 0.1" material="grid" solimp=".9 .95 .001" solref='-10000 -1000'  contype="3" conaffinity="3" />
  </worldbody>

  <option timestep="0.0025" iterations="20" integrator="implicitfast" gravity="0 0 -9.81"/>
  <contact>
    <exclude body1='arm_base' body2='link2'/>
    <exclude body1='arm_base' body2='link1'/>
    <exclude body1='link1' body2='link2'/>
    <exclude body1='link2' body2='link3'/>
    <exclude body1='link3' body2='link4'/>
    <exclude body1='link4' body2='link5'/>
    <exclude body1='link5' body2='link6'/>
    <exclude body1='link6' body2='right'/>
    <exclude body1='link6' body2='left'/>
  </contact>

  <!-- <compiler angle="radian" inertiafromgeom="true"/> -->
  <compiler angle="radian" inertiafromgeom="auto" inertiagrouprange="22 22" />
  <size njmax="10000" nconmax="10000"/>

  <tendon>
    <fixed name='gripper_gear'>
      <joint joint='endleft'  coef='-12.5'/>
      <joint joint='endright' coef='12.5'/>
    </fixed>
  </tendon> 
  <default>
    <!-- <default class="arm_visual">
      <geom contype="1" conaffinity="0" condim="4"/>
    </default> -->
    <geom contype="0" conaffinity="0" condim="4"/>
    <default class='arm'>
      <default class='joint1'>
        <joint axis='0 0 1' range="-3.14 2.09" actuatorfrcrange="-24 24" damping="0.2" frictionloss='15' />
        <position ctrlrange="-3.14 2.09"/>
      </default>

      <default class='joint2'>
        <joint axis='0 0 1' range="-2.96 0.17" actuatorfrcrange="-24 24" damping="0.2" frictionloss='15' />
        <position ctrlrange="-2.96 0.17" />
      </default>

      <default class='joint3'>
        <joint axis='0 0 1' range='-0.087 3.14' actuatorfrcrange="-24 24" damping="0.2" frictionloss='15' />
        <position ctrlrange='-0.087 3.14'/>
      </default>

      <default class='joint4'>
        <joint axis='0 0 1' range="1.569 1.571" damping="0.1" frictionloss='5' />
      </default>

      <default class='joint5'>
        <joint axis='0 0 1' range="-1.74 1.74" actuatorfrcrange="-8 8" damping="0.1" frictionloss='5' />
        <position ctrlrange="-1.74 1.74"/>
      </default>

      <default class='joint6'>
        <joint axis='0 0 1' range="-3.14 3.14" actuatorfrcrange="-8 8" damping="0.1" frictionloss='5' />
        <position ctrlrange="-3.14 3.14"/>
      </default>

      <default class='finger1'>
        <joint axis='0 1 0' range="-0.0331 -0.0329" type='slide' damping="0.5" frictionloss="15"/>
      </default>

      <default class='finger2'>
        <joint axis='0 1 0' range="0.0329 0.0331" type='slide' damping="0.5" frictionloss="15"/>
      </default>
    </default>
 </default>
  
  <worldbody>
    <!-- ======= AITBOT PLAY ======= -->
    <body name="arm_pose" pos="0 0 0.78" euler="0 0 0">
        <body name="arm_base">
            <geom type="box" pos="-0.02 0 0.005" size="0.0806 0.1375 0.0025" rgba="0.2 0.2 0.2 1" euler="0 0 1.5708" contype="0" conaffinity="1"/>
            <geom type="box" pos="-0.015 0 0.045" size="0.07 0.05 0.04" rgba="1 0 0 0.5" contype="0" conaffinity="1"/>
            <body name="link1" pos="0 0 0.1172">
            <inertial pos="7.9126e-05 -0.002527 -0.0041359" quat="0.696716 0.716558 0.0238919 -0.0236876" mass="0.54639" diaginertia="0.000346294 0.000325437 0.000286269"/>
            <joint name="joint1" class="joint1"/>
            <body name="link2" quat="0.135866 0.135867 -0.69393 0.693932">
                <inertial pos="0.22493 0.0047721 0.008023" quat="-0.210875 0.632473 -0.273056 0.693506" mass="0.64621" diaginertia="0.00516535 0.00505042 0.000418626"/>
                <joint name="joint2" class="joint2"/>
                <geom type="box" pos="0.08 0.015 0" euler="0 0 0.15" size="0.11 0.03 0.04" rgba="1 0 0 0.8" contype="0" conaffinity="1"/>
                <geom type="box" pos="0.235 0.015 0" euler="0 0 -0.3" size="0.065 0.025 0.045" rgba="1 0 0 0.8" contype="0" conaffinity="1"/>
                <body name="link3" pos="0.27009 0 0" quat="0.192144 0 0 -0.981367">
                <inertial pos="0.16813 -5.5576e-05 0.0031184" quat="0.511278 0.488423 0.489191 0.510617" mass="0.26829" diaginertia="0.0031527 0.0030951 0.000239403"/>
                <joint name="joint3" class="joint3"/>
                <geom type="box" pos="0.13 0 0" size="0.13 0.025 0.025" rgba="1 0 0 0.8" contype="0" conaffinity="1"/>
                <body name="link4" pos="0.29015 0 0" quat="-2.59734e-06 0.707105 2.59735e-06 0.707108">
                    <inertial pos="5.2436e-06 0.00040412 -0.03228" quat="0.999969 -0.000174762 -0.00792041 -6.98144e-05" mass="0.34876" diaginertia="0.000423574 0.000412 0.000126826"/>
                    <joint name="joint4" class="joint4" />
                    <geom type="box" pos="0 0 0" size="0.03 0.03 0.03"  rgba="1 0 0 0.8" contype="0" conaffinity="1"/>
                    <body name="link5" quat="0.707105 0.707108 0 0">
                    <inertial pos="8.3328e-06 0.026148 0.002525" quat="0.531568 0.4663 0.4663 0.531568" mass="0.36132" diaginertia="0.0004677 0.000432922 0.000178178"/>
                    <joint name="joint5" class="joint5"/>
                    <geom type="box" pos="0 0.06 0" size="0.03 0.03 0.03" rgba="1 0 0 0.8" contype="0" conaffinity="1"/>
                    <body name="link6" pos="0 0.23645 0" quat="0.499998 -0.5 0.5 0.500002">
                        <inertial pos="-0.0047053 7.3857e-05 -0.12293" mass="0.53855" diaginertia="5e-05 5e-05 3.85e-05"/>
                        <joint name="joint6" class="joint6"/>
                        <geom type="box" pos="0 0 -0.11" size="0.03 0.03 0.03" rgba="1 0 0 0.8" contype="0" conaffinity="1"/>
                        <geom name="fixed_gripper" type="box" pos="0 0 -0.07" size="0.025 0.08 0.015" rgba="1 0 0 0.8" contype="0" conaffinity="1"/>
                        <site name="endpoint" pos='0 0 0.025' euler="0 -1.5708 0" size='0.001' type='sphere'/>
                        <body name="right" pos="0 0 0" quat="9.38184e-07 0.707105 -9.38187e-07 0.707108">
                        <inertial pos="-0.048742 0.0096369 0.00044322" quat="0.757393 0.0415116 0.0313705 0.650883" mass="0.0626" diaginertia="2.79281e-05 1.90181e-05 1.21737e-05"/>
                        <joint name="endright" class='finger2'/>
                        <geom   condim="4" solimp="0.8 1 0.01" solref="0.01 1" friction="1 0.005 0.0001" type="box" pos="0.012 0.002 0.002" size="0.012 0.002 0.01" rgba="1 0 0 0.8" contype="0" conaffinity="1"/>
                        <geom   condim="4" solimp="0.8 1 0.01" solref="0.01 1" friction="1 0.005 0.0001" type="box" pos="-0.012 0.002 0.005" size="0.012 0.002 0.02" rgba="1 0 0 0.8" contype="0" conaffinity="1"/>
                        <geom   condim="4" solimp="0.8 1 0.01" solref="0.01 1" friction="1 0.005 0.0001" type="box" pos="-0.036 0.002 0.00" size="0.012 0.002 0.03" rgba="1 0 0 0.8" contype="0" conaffinity="1" name="right_finger"/>
                        </body>
                        <body name="left" pos="0 0 0" quat="9.38184e-07 0.707105 -9.38187e-07 0.707108">
                        <inertial pos="-0.049039 -0.0096764 0.00038868" quat="0.650491 0.0296695 0.0398251 0.757889" mass="0.061803" diaginertia="2.74809e-05 1.88104e-05 1.19127e-05"/>
                        <joint name="endleft" class='finger1'/>
                        <geom   condim="4" solimp="0.8 1 0.01" solref="0.01 1" friction="1 0.005 0.0001" type="box" pos="0.012 -0.002 0.002" size="0.012 0.002 0.01" rgba="1 0 0 0.8" contype="0" conaffinity="1"/>
                        <geom   condim="4" solimp="0.8 1 0.01" solref="0.01 1" friction="1 0.005 0.0001" type="box" pos="-0.012 -0.002 0.005" size="0.012 0.002 0.02" rgba="1 0 0 0.8" contype="0" conaffinity="1"/>
                        <geom   condim="4" solimp="0.8 1 0.01" solref="0.01 1" friction="1 0.005 0.0001" type="box" pos="-0.036 -0.002 0.00" size="0.012 0.002 0.03" rgba="1 0 0 0.8" contype="0" conaffinity="1" name="left_finger"/>
                        </body>
                    </body>
                    </body>
                </body>
                </body>
            </body>
            </body>
        </body>
      </body>

    <body name="table-a" pos="0.2 0 0">
      <!-- 桌面 -->
      <geom size="0.8 0.3 0.01" pos="0 0 0.77" type="box" rgba="0.8 0.8 0.8 1"  
      condim="4" solimp="0.8 1 0.01" solref="0.01 1" friction="1 0.005 0.0001" 
      contype="3" conaffinity="3" name="table-b" />
      <!-- 桌腿 -->
      <geom size="0.02 0.02 0.385" pos=" 0.56 -0.28 0.385" type="box" contype="0" conaffinity="0" rgba="0.8 0.8 0.8 1" />
      <geom size="0.02 0.02 0.385" pos=" 0.56  0.28 0.385" type="box" contype="0" conaffinity="0" rgba="0.8 0.8 0.8 1" />
      <geom size="0.02 0.02 0.385" pos="-0.56 -0.28 0.385" type="box" contype="0" conaffinity="0" rgba="0.8 0.8 0.8 1" />
      <geom size="0.02 0.02 0.385" pos="-0.56  0.28 0.385" type="box" contype="0" conaffinity="0" rgba="0.8 0.8 0.8 1" />
    </body>

    <body name="target_pos" pos="0.4664427 0.10352592 0.81999997">
      <geom type="box" name="target" size="0.04 0.04 0.04" rgba="0 0 1 1" contype="0" conaffinity="2" mass="0"/>
      <inertial pos="0 0 0" mass="0.5" diaginertia="0.0005333 0.0005333 0.0005333"/>
      <freejoint/>
    </body>

    <body name="cube_for_push" pos="0.32 0.0 0.82">
      <freejoint/>
      <inertial pos="0 0 0" mass="0.5" diaginertia="0.0005333 0.0005333 0.0005333"/>
      <geom type="box" solimp="0.8 1 0.01" solref="0.01 1" name="geom_for_push" size="0.04 0.04 0.04" condim="4"
       friction="1 0.1 0.1" rgba="1 0 0 1" contype="1" conaffinity="0" />
    </body>

  </worldbody>

  <equality>
    <joint joint1='endleft' joint2='endright' polycoef='0 -1 0 0 0 '/>
  </equality>

  <actuator>
    <position name="joint1" ctrllimited="true" ctrlrange="-3.14 2.09"  joint="joint1" kp="1000" user="1" forcelimited="true" forcerange="-300 300"/>
    <position name="joint2" ctrllimited="true" ctrlrange="-2.96 0.17"  joint="joint2" kp="1000" user="1" forcelimited="true" forcerange="-300 300"/>
    <position name="joint3" ctrllimited="true" ctrlrange="-0.087 3.14" joint="joint3" kp="1000" user="1" forcelimited="true" forcerange="-300 300"/>
    <!-- <position name="joint4" ctrllimited="true" ctrlrange="-2.96 2.96"  joint="joint4" kp="350" user="1" forcelimited="true" forcerange="-300 300"/> -->
    <position name="joint5" ctrllimited="true" ctrlrange="-1.74 1.74"  joint="joint5" kp="350" user="1" forcelimited="true" forcerange="-300 300"/>
    <position name="joint6" ctrllimited="true" ctrlrange="-3.14 3.14"  joint="joint6" kp="100" user="1" forcelimited="true" forcerange="-300 300"/>
    <!-- <position name='gripper' tendon='gripper_gear' ctrllimited="true" ctrlrange="0. 1." kp="3" user="1" forcelimited="true" forcerange="-1 1"/> -->
  </actuator>

</mujoco>